Workbook
Name Slicer_Area: #N/A
Name Slicer_Department: #N/A

Sheet Dashboard
E9: =GETPIVOTDATA("Salary",Pivots!$X$5) -> 183 | L9: =GETPIVOTDATA("Salary",Pivots!$X$9) -> 14122790 | Q9: =GETPIVOTDATA("Salary",Pivots!$X$17) -> 77173.716 | W9: =(GETPIVOTDATA("Count Bonus",Pivots!$X$14)/GETPIVOTDATA("Salary",Pivots!$X$5)) -> 0.98360656

Sheet Key Insights
B2: Key Insights
B6: 1. Women earn more than men on average here, which the opposite of the usual pay-gap story. - Female average salary is $78,284 vs. Male at $74,915. This holds in four of five departments (Finance, HR, Procurement, Sales). - Only Website runs the other way, where men average $86,408 vs. women at $70,989, a genuinely large gap worth a closer look on its own.
B10: 2. Performance ratings barely track with pay. - Average salary by rating is nearly flat: Very Poor ($77,423), Poor ($78,115), Average ($76,799), Above Average ($75,933) all sit within about $2,200 of each other. - Only "Exceptional" breaks away, at $92,080. In fact, the five highest individual salaries in the company all belong to employees rated "Average". - The pay scale doesn't appear to reward performance below the top tier.
B15: 3. Neither age nor tenure meaningfully predicts salary. - The correlation between Salary and Age is 0.07; between Salary and Tenure it's 0.01, thus both are essentially zero. - Pay here is not structured around seniority or experience.
B19: 4. Three employees received no bonus at all, out of 183 (98% did). - Their ratings and tenure look unremarkable compared to bonus recipients, so there is no obvious pattern explaining the gap.
B23: 5. Procurement and Website carry the most headcount and pay the most on average (excluding the very small HR team of 8). - HR has the highest average salary company-wide ($89,650) but is also the smallest department by far , worth noting since a small team average is more easily skewed by one or two high earners.
B27: 6. Gender distribution varies sharply by department. - Procurement is 35 Male vs. 20 Female (0 Other); HR is 6 Female vs. 2 Male. - Website is the only department with a meaningful "Other" gender presence (4 people) and is also the one department where the pay gap runs against women.
B31: Action Items
B35: 1. Investigate the Website department's gender pay gap specifically. -It is the one place where the company-wide "women earn more" pattern reverses, and by a wide margin — worth understanding whether that's role/seniority mix or something else before it becomes a compliance question.
B38: 2. Review whether performance ratings should influence pay more than they currently do. - With Poor and Very Poor performers earning about the same as Average performers, the current pay structure doesn't obviously incentivize the rating system it uses.
B41: 3. Check the three zero-bonus employees individually. - Confirm whether it's a deliberate policy reason (e.g. probation period, recent start) or a data entry gap.
B44: 4. Address the Procurement/HR gender skew if diversity metrics matter to Nexora's reporting. - Both departments sit well outside a roughly even split.

Sheet Pivots
B3: Slicer: Area | J3: Slicer: Area, Dept
A5: Average of Salary | B5: Column Labels | G5: Row Labels | H5: Average of Salary | J5: Row Labels | K5: Max of Salary | M5: Row Labels | N5: Average of Salary | P5: Row Labels | Q5: Count of Salary | S5: Row Labels | T5: Average of Salary | U5: Sum of Bonus | X5: Count of Salary
A6: Row Labels | B6: Female | C6: Male | D6: Other | E6: Grand Total | G6: 19 | H6: 58960 | J6: Benny Karolovsky | K6: 115440 | M6: Female | N6: 78284.186 | P6: Female | Q6: 86 | S6: 3.9722222 | T6: 112570 | U6: 0 | X6: 183
A7: Finance | B7: 73138.889 | C7: 67411.25 | D7: 89720 | E7: 72472.632 | G7: 20 | H7: 92205 | J7: Sahila Chandrasekhar | K7: 115440 | M7: Male | N7: 74915.169 | P7: Male | Q7: 89 | S7: 4.0027778 | T7: 91945 | U7: 220668
A8: HR | B8: 94240 | C8: 75880 | E8: 89650 | G8: 21 | H8: 54146 | J8: Roddy Speechley | K8: 115920 | M8: Other | N8: 90362.5 | P8: Other | Q8: 8 | S8: 4.0861111 | T8: 43510 | U8: 52212
A9: Procurement | B9: 92236 | C9: 75827.143 | E9: 81794 | G9: 22 | H9: 94840 | J9: Sarayu Ragunathan | K9: 115920 | M9: Grand Total | N9: 77173.716 | P9: Grand Total | Q9: 183 | S9: 4.1166667 | T9: 86570 | U9: 103884 | X9: Sum of Salary
A10: Sales | B10: 72720 | C10: 63012.857 | E10: 67866.429 | G10: 23 | H10: 106460 | J10: Kaishori Harathi Kateel | K10: 118100 | S10: 4.1416667 | T10: 112570 | U10: 135084 | X10: 14122790
A11: Website | B11: 70989.286 | C11: 86408.182 | D11: 91005 | E11: 78753.704 | G11: 24 | H11: 71936.667 | J11: Valentia Etteridge | K11: 118100 | S11: 4.2 | T11: 75000 | U11: 90000
A12: Grand Total | B12: 78284.186 | C12: 74915.169 | D12: 90362.5 | E12: 77173.716 | G12: 25 | H12: 87072.5 | J12: Heer Pennathur | K12: 118840 | S12: 4.2138889 | T12: 91310 | U12: 109572
G13: 26 | H13: 58500 | J13: Tawnya Tickel | K13: 118840 | S13: 4.4805556 | T13: 33920 | U13: 40704
G14: 27 | H14: 85706.154 | J14: Anjushri Chandiramani | K14: 119110 | S14: 4.55 | T14: 58940 | U14: 70728 | X14: Sum of Count Bonus
G15: 28 | H15: 75678.571 | J15: Ewart Laphorn | K15: 119110 | S15: 4.6638889 | T15: 60130 | U15: 72156 | X15: 180
G16: 29 | H16: 73545 | J16: Grand Total | K16: 119110 | S16: 4.6777778 | T16: 60570 | U16: 72684
G17: 30 | H17: 80312.222 | S17: 4.7888889 | T17: 48980 | U17: 58776 | X17: Average of Salary
G18: 31 | H18: 63145 | S18: 4.8361111 | T18: 60130 | U18: 72156 | X18: 77173.716
G19: 32 | H19: 55154 | S19: 4.8527778 | T19: 96800 | U19: 116160
G20: 33 | H20: 75113 | S20: 4.9583333 | T20: 48980 | U20: 58776
G21: 34 | H21: 73177.273 | S21: 5.1416667 | T21: 106460 | U21: 127752
G22: 35 | H22: 40400 | S22: 5.2444444 | T22: 53540 | U22: 64248
G23: 36 | H23: 92408 | S23: 5.2944444 | T23: 74550 | U23: 89460
G24: 37 | H24: 97665 | S24: 5.3055556 | T24: 104410 | U24: 125292
G25: 38 | H25: 83015 | S25: 5.3722222 | T25: 53240 | U25: 63888
G26: 40 | H26: 97260 | S26: 5.3916667 | T26: 53540 | U26: 64248
G27: 42 | H27: 72635 | S27: 5.4944444 | T27: 75480 | U27: 90576
G28: 43 | H28: 62316.667 | S28: 5.4972222 | T28: 75280 | U28: 90336
G29: 44 | H29: 114870 | S29: 5.5416667 | T29: 53240 | U29: 63888
G30: 46 | H30: 70610 | S30: 5.6111111 | T30: 90700 | U30: 108840
G31: Grand Total | H31: 77173.716 | S31: 5.8361111 | T31: 96140 | U31: 115368
S32: 6.0055556 | T32: 96140 | U32: 115368
S33: 4.7138889 | T33: 58940 | U33: 70728
S34: 5.4527778 | T34: 67910 | U34: 81492
S35: 5.2222222 | T35: 53540 | U35: 64248
S36: 5.55 | T36: 43840 | U36: 52608
S37: 4.8722222 | T37: 68900 | U37: 82680
S38: 5.4388889 | T38: 71380 | U38: 85656
S39: 4.5805556 | T39: 112650 | U39: 135180
S40: 5.425 | T40: 88050 | U40: 105660
S41: 5.1833333 | T41: 104770 | U41: 125724
S42: 5.0722222 | T42: 53540 | U42: 64248
S43: 5.0138889 | T43: 104770 | U43: 125724
...

Sheet Cleaned Data
B2: Employee | C2: Gender | D2: Department | E2: Age | F2: Date Joined | G2: Salary | H2: Rating | I2: Area | J2: Tenure | K2: Bonus | M2: Employees receive a 20% bonus based on eligibility criteria.
A3: Select Name: | B3: Bennie Pepis | C3: {=_xlfn.XLOOKUP(B3,Employee_Details[Name],Employee_Details[[Gender]:[Bonus]],"N/A")} -> Male | D3: Finance | E3: 36 | F3: 44333 | G3: 71380 | H3: Average | I3: New Zealand | J3: 5.475 | K3: 85656
B5: Name | C5: Gender | D5: Department | E5: Age | F5: Date Joined | G5: Salary | H5: Rating | I5: Area | J5: Tenure | K5: Bonus | L5: Count Bonus
B6: Abhaya Priyavardhan | C6: Male | D6: Sales | E6: 25 | F6: 44322 | G6: 65700 | H6: Average | I6: India | J6: =(Calculations!$C$19-Employee_Details[[#This Row],[Date Joined]])/360 -> 5.5055556 | K6: =IF(Employee_Details[[#This Row],[Tenure]]>4,1.2*Employee_Details[[#This Row],[Salary]],0) -> 78840 | L6: =IF(Employee_Details[[#This Row],[Bonus]]>0,1,0) -> 1 | O6: =COUNTIF(Employee_Details[Count Bonus],">"&0) -> 181
B7: Agnes Collicott | C7: Female | D7: Website | E7: 27 | F7: 44686 | G7: 83750 | H7: Average | I7: New Zealand | J7: =(Calculations!$C$19-Employee_Details[[#This Row],[Date Joined]])/360 -> 4.4944444 | K7: =IF(Employee_Details[[#This Row],[Tenure]]>4,1.2*Employee_Details[[#This Row],[Salary]],0) -> 100500 | L7: =IF(Employee_Details[[#This Row],[Bonus]]>0,1,0) -> 1 | O7: =COUNTA(Employee_Details[Count Bonus]) -> 183
B8: Agrata Rajarama | C8: Female | D8: Finance | E8: 21 | F8: 44256 | G8: 65920 | H8: Average | I8: India | J8: =(Calculations!$C$19-Employee_Details[[#This Row],[Date Joined]])/360 -> 5.6888889 | K8: =IF(Employee_Details[[#This Row],[Tenure]]>4,1.2*Employee_Details[[#This Row],[Salary]],0) -> 79104 | L8: =IF(Employee_Details[[#This Row],[Bonus]]>0,1,0) -> 1 | O8: =O6/O7 -> 0.98907104
B9: Akbar Sorabhjee | C9: Male | D9: Procurement | E9: 21 | F9: 44042 | G9: 37920 | H9: Average | I9: India | J9: =(Calculations!$C$19-Employee_Details[[#This Row],[Date Joined]])/360 -> 6.2833333 | K9: =IF(Employee_Details[[#This Row],[Tenure]]>4,1.2*Employee_Details[[#This Row],[Salary]],0) -> 45504 | L9: =IF(Employee_Details[[#This Row],[Bonus]]>0,1,0) -> 1
B10: Allene Gobbet | C10: Female | D10: Procurement | E10: 36 | F10: 44529 | G10: 78390 | H10: Average | I10: New Zealand | J10: =(Calculations!$C$19-Employee_Details[[#This Row],[Date Joined]])/360 -> 4.9305556 | K10: =IF(Employee_Details[[#This Row],[Tenure]]>4,1.2*Employee_Details[[#This Row],[Salary]],0) -> 94068 | L10: =IF(Employee_Details[[#This Row],[Bonus]]>0,1,0) -> 1
B11: Alta Kaszper | C11: Male | D11: Sales | E11: 27 | F11: 44134 | G11: 54970 | H11: Average | I11: New Zealand | J11: =(Calculations!$C$19-Employee_Details[[#This Row],[Date Joined]])/360 -> 6.0277778 | K11: =IF(Employee_Details[[#This Row],[Tenure]]>4,1.2*Employee_Details[[#This Row],[Salary]],0) -> 65964 | L11: =IF(Employee_Details[[#This Row],[Bonus]]>0,1,0) -> 1
B12: Amal Nimesh | C12: Male | D12: Website | E12: 31 | F12: 44450 | G12: 48950 | H12: Average | I12: India | J12: =(Calculations!$C$19-Employee_Details[[#This Row],[Date Joined]])/360 -> 5.15 | K12: =IF(Employee_Details[[#This Row],[Tenure]]>4,1.2*Employee_Details[[#This Row],[Salary]],0) -> 58740 | L12: =IF(Employee_Details[[#This Row],[Bonus]]>0,1,0) -> 1
B13: Ambros Murthwaite | C13: Male | D13: Procurement | E13: 46 | F13: 44758 | G13: 70610 | H13: Average | I13: New Zealand | J13: =(Calculations!$C$19-Employee_Details[[#This Row],[Date Joined]])/360 -> 4.2944444 | K13: =IF(Employee_Details[[#This Row],[Tenure]]>4,1.2*Employee_Details[[#This Row],[Salary]],0) -> 84732 | L13: =IF(Employee_Details[[#This Row],[Bonus]]>0,1,0) -> 1
B14: Amlankusum Rajabhushan | C14: Male | D14: Website | E14: 24 | F14: 44625 | G14: 100420 | H14: Average | I14: India | J14: =(Calculations!$C$19-Employee_Details[[#This Row],[Date Joined]])/360 -> 4.6638889 | K14: =IF(Employee_Details[[#This Row],[Tenure]]>4,1.2*Employee_Details[[#This Row],[Salary]],0) -> 120504 | L14: =IF(Employee_Details[[#This Row],[Bonus]]>0,1,0) -> 1
B15: Andria Kimpton | C15: Male | D15: Website | E15: 30 | F15: 44273 | G15: 69120 | H15: Average | I15: New Zealand | J15: =(Calculations!$C$19-Employee_Details[[#This Row],[Date Joined]])/360 -> 5.6416667 | K15: =IF(Employee_Details[[#This Row],[Tenure]]>4,1.2*Employee_Details[[#This Row],[Salary]],0) -> 82944 | L15: =IF(Employee_Details[[#This Row],[Bonus]]>0,1,0) -> 1
B16: Anjushri Chandiramani | C16: Female | D16: HR | E16: 27 | F16: 44061 | G16: 119110 | H16: Average | I16: India | J16: =(Calculations!$C$19-Employee_Details[[#This Row],[Date Joined]])/360 -> 6.2305556 | K16: =IF(Employee_Details[[#This Row],[Tenure]]>4,1.2*Employee_Details[[#This Row],[Salary]],0) -> 142932 | L16: =IF(Employee_Details[[#This Row],[Bonus]]>0,1,0) -> 1
B17: Anumati Shyamari Meherhomji | C17: Female | D17: Sales | E17: 28 | F17: 44296 | G17: 53240 | H17: Average | I17: India | J17: =(Calculations!$C$19-Employee_Details[[#This Row],[Date Joined]])/360 -> 5.5777778 | K17: =IF(Employee_Details[[#This Row],[Tenure]]>4,1.2*Employee_Details[[#This Row],[Salary]],0) -> 63888 | L17: =IF(Employee_Details[[#This Row],[Bonus]]>0,1,0) -> 1
B18: Archibald Filliskirk | C18: Male | D18: Procurement | E18: 35 | F18: 44727 | G18: 40400 | H18: Average | I18: New Zealand | J18: =(Calculations!$C$19-Employee_Details[[#This Row],[Date Joined]])/360 -> 4.3805556 | K18: =IF(Employee_Details[[#This Row],[Tenure]]>4,1.2*Employee_Details[[#This Row],[Salary]],0) -> 48480 | L18: =IF(Employee_Details[[#This Row],[Bonus]]>0,1,0) -> 1
B19: Ardhendu Abhichandra Jayakar | C19: Male | D19: Finance | E19: 28 | F19: 43980 | G19: 48170 | H19: Above average | I19: India | J19: =(Calculations!$C$19-Employee_Details[[#This Row],[Date Joined]])/360 -> 6.4555556 | K19: =IF(Employee_Details[[#This Row],[Tenure]]>4,1.2*Employee_Details[[#This Row],[Salary]],0) -> 57804 | L19: =IF(Employee_Details[[#This Row],[Bonus]]>0,1,0) -> 1
B20: Asija Pothireddy | C20: Male | D20: Finance | E20: 33 | F20: 44181 | G20: 59430 | H20: Average | I20: India | J20: =(Calculations!$C$19-Employee_Details[[#This Row],[Date Joined]])/360 -> 5.8972222 | K20: =IF(Employee_Details[[#This Row],[Tenure]]>4,1.2*Employee_Details[[#This Row],[Salary]],0) -> 71316 | L20: =IF(Employee_Details[[#This Row],[Bonus]]>0,1,0) -> 1
... B188: Zach Polon | C188: Male | D188: Procurement | E188: 26 | F188: 44411 | G188: 53540 | H188: Average | I188: New Zealand | J188: =(Calculations!$C$19-Employee_Details[[#This Row],[Date Joined]])/360 -> 5.2583333 | K188: =IF(Employee_Details[[#This Row],[Tenure]]>4,1.2*Employee_Details[[#This Row],[Salary]],0) -> 64248 | L188: =IF(Employee_Details[[#This Row],[Bonus]]>0,1,0) -> 1
C189: =SUBTOTAL(103,C6:C188) -> 183 | E189: =SUBTOTAL(101,E6:E188) -> 30.42623 | G189: =SUBTOTAL(101,Employee_Details[Salary]) -> 77173.716 | H189: =SUBTOTAL(103,Employee_Details[Rating]) -> 183 | K189: =SUBTOTAL(101,Employee_Details[Bonus]) -> 91101.967

Sheet Calculations
B2: Insight Calculations
B3: No of employees | C3: =COUNTA(Employee_Details[Gender]) -> 183
B4: Average Salary | C4: =AVERAGE(Employee_Details[Salary]) -> 77173.716
B5: Median Salary | C5: =MEDIAN(Employee_Details[Salary]) -> 75000
B6: Average Age | C6: =AVERAGE(Employee_Details[Age]) -> 30.42623
B7: Number of Males | C7: =COUNTIF(Employee_Details[Gender],'Cleaned Data'!C6) -> 89
B8: Number of Females | C8: =COUNTIF(Employee_Details[Gender],'Cleaned Data'!C8) -> 86
B9: Female/Male Ration | C9: =C8/(C7) -> 0.96629213
B10: Number of Employees earning below the mean | C10: =COUNTIFS(Employee_Details[Salary],"<"&'Cleaned Data'!G189) -> 102
B19: Today's Date | C19: =TODAY() -> 46304

Sheet Cleaned Data_NZ staff
C1: 1 | D1: 2 | E1: 3 | F1: 4 | G1: 6 | H1: 7 | I1: 5 | J1: 8
C2: Name | D2: Gender | E2: Department | F2: Age | G2: Rating | H2: Date Joined | I2: Salary | J2: Area
C3: Lindy Guillet | D3: Male | E3: Sales | F3: 22 | G3: Above average | H3: 44446 | I3: 112780 | J3: New Zealand
C4: Ambros Murthwaite | D4: Male | E4: Procurement | F4: 46 | G4: Average | H4: 44758 | I4: 70610 | J4: New Zealand
C5: Tatum Hush | D5: Female | E5: Sales | F5: 28 | G5: Average | H5: 44357 | I5: 53240 | J5: New Zealand
C6: Benny Karolovsky | D6: Other | E6: Finance | F6: 37 | G6: Poor | H6: 44146 | I6: 115440 | J6: New Zealand
C7: Hoyt D'Alesco | D7: Male | E7: Sales | F7: 32 | G7: Average | H7: 44465 | I7: 53540 | J7: New Zealand
C8: Halimeda Kuscha | D8: Female | E8: Procurement | F8: 30 | G8: Average | H8: 44861 | I8: 112570 | J8: New Zealand
C9: Erin Androsik | D9: Male | E9: Procurement | F9: 33 | G9: Above average | H9: 44701 | I9: 48530 | J9: New Zealand
C10: Vic Radolf | D10: Female | E10: Website | F10: 24 | G10: Average | H10: 44148 | I10: 62780 | J10: New Zealand
C11: William Reeveley | D11: Male | E11: Website | F11: 33 | G11: Average | H11: 44509 | I11: 53870 | J11: New Zealand
C12: Ewart Laphorn | D12: Female | E12: HR | F12: 27 | G12: Average | H12: 44122 | I12: 119110 | J12: New Zealand
C13: Bev Lashley | D13: Male | E13: Website | F13: 29 | G13: Poor | H13: 44180 | I13: 112110 | J13: New Zealand
C14: Kath Bletsoe | D14: Male | E14: Sales | F14: 25 | G14: Average | H14: 44383 | I14: 65700 | J14: New Zealand
... C93: Zach Polon | D93: Male | E93: Procurement | F93: 26 | G93: Average | H93: 44411 | I93: 53540 | J93: New Zealand

Sheet Cleaned Data_Ind Staff
B2: Name | C2: Gender | D2: Department | E2: Age | F2: Rating | G2: Date Joined | H2: Salary | I2: Area
B3: Deepali Charan | C3: Male | D3: Website | E3: 20 | F3: Average | G3: 44122 | H3: 112650 | I3: India
B4: Yagna Sujeev | C4: Female | D4: Website | E4: 32 | F4: Above average | G4: 44293 | H4: 43840 | I4: India
B5: Satyendra Venkatadri | C5: Male | D5: Procurement | E5: 31 | F5: Average | G5: 44663 | H5: 103550 | I5: India
B6: Madhavdas Buhpathi | C6: Female | D6: HR | E6: 32 | F6: Average | G6: 44339 | H6: 45510 | I6: India
B7: Sahila Chandrasekhar | C7: Other | D7: Finance | E7: 37 | F7: Poor | G7: 44085 | H7: 115440 | I7: India
B8: Mirium Seemantini Shivakumar | C8: Female | D8: Sales | E8: 38 | F8: Above average | G8: 44268 | H8: 56870 | I8: India
B9: Purnendu Vijayarangan | C9: Female | D9: Sales | E9: 25 | F9: Average | G9: 44144 | H9: 92700 | I9: India
B10: Rukma Vinita | C10: Other | D10: Website | E10: 32 | F10: Average | G10: 44713 | H10: 91310 | I10: India
B11: Yauvani Tarpa | C11: Male | D11: Sales | E11: 33 | F11: Average | G11: 44324 | H11: 74550 | I11: India
B12: Damayanti Thangavadivelu | C12: Male | D12: Procurement | E12: 25 | F12: Above average | G12: 44665 | H12: 109190 | I12: India
B13: Manjusri Ruchi | C13: Female | D13: Website | E13: 40 | F13: Average | G13: 44320 | H13: 104410 | I13: India
B14: Mithil Nadkarni | C14: Male | D14: Finance | E14: 30 | F14: Average | G14: 44544 | H14: 96800 | I14: India
... B94: Sukhdev Nageshwar | C94: Female | D94: Website | E94: 33 | F94: Average | G94: 44129 | H94: 96140 | I94: India
B95: Total | C95: =SUBTOTAL(103,Table2[Gender]) -> 92 | E95: =SUBTOTAL(101,Table2[Age]) -> 30.456522 | H95: =SUBTOTAL(109,Table2[Salary]) -> 7117720

Sheet Raw Data 1
C1: Dataset: Synthetic HR employee data created for analytics and dashboarding purposes.
C3: Agnes Collicott | D3: 44686 | E3: Website | F3: 27 | G3: Female | H3: Average | I3: 83750
C4: Allene Gobbet | D4: 44529 | F4: Procurement | G4: 36 | H4: Female | I4: Average | J4: 78390
C5: Alta Kaszper | D5: 44134 | E5: Sales | F5: 27 | G5: Male | H5: Average | I5: 54970
D6: 44758 | E6: Procurement | F6: 46 | G6: Male | H6: Average | I6: 70610 | J6: Ambros Murthwaite
C7: Ambros Murthwaite | D7: 44758 | E7: Procurement | F7: 46 | G7: Male | H7: Average | I7: 70610
C8: Andria Kimpton | D8: 44273 | E8: Website | F8: 30 | G8: Male | H8: Average | I8: 69120
C9: Archibald Filliskirk | D9: 44727 | E9: Procurement | F9: 35 | G9: Male | H9: Average | I9: 40400
C10: Barr Faughny | D10: 44779 | E10: Procurement | F10: 42 | G10: Female | H10: Exceptional | I10: 75000
D11: Bennie Pepis | E11: 44333 | F11: Finance | H11: 36 | I11: Male | J11: Average | K11: 71380
C12: Benny Karolovsky | D12: 44146 | E12: Finance | F12: 37 | H12: Poor | I12: 115440
C13: Benny Karolovsky | D13: 44146 | E13: Finance | F13: 37 | H13: Poor | I13: 115440
C14: Bernie Gorges | D14: 44630 | F14: Procurement | G14: 28 | H14: Female | I14: Average | J14: 99970
C15: Bev Lashley | D15: 44180 | E15: Website | F15: 29 | G15: Male | H15: Poor | I15: 112110
C16: Beverie Moffet | D16: 44185 | E16: Finance | F16: 28 | G16: Female | H16: Average | I16: 75970
D17: 44620 | E17: Sales | F17: 43 | G17: Male | H17: Average | I17: 36040 | J17: Bili Sizey
D18: 44663 | E18: Website | F18: 31 | G18: Female | H18: Average | I18: 58100 | J18: Brien Boise
D19: 44374 | E19: Website | F19: 33 | G19: Female | H19: Very poor | I19: 75480 | J19: Camilla Castle
C20: Caro Chappel | D20: 44381 | E20: Website | F20: 40 | G20: Female | H20: Average | I20: 104410
C21: Cherlyn Barter | D21: 44649 | E21: Procurement | F21: 28 | G21: Female | H21: Average | I21: 104120
C22: Ches Bonnell | D22: 44338 | E22: Website | F22: 37 | G22: Male | H22: Poor | I22: 88050
C23: Collin Jagson | D23: 44686 | F23: Website | G23: 24 | H23: Male | I23: Average | J23: 100420
C24: Constantino Espley | D24: 44606 | E24: Finance | F24: 30 | G24: Male | H24: Average | I24: 96800
C25: Crissie Cordel | D25: 44611 | E25: Procurement | F25: 32 | G25: Female | H25: Average | I25: 41570
C26: Curtice Advani | D26: 44597 | E26: Finance | F26: 30 | H26: Average | I26: 64000
C27: Dell Molloy | D27: 44225 | E27: Procurement | F27: 26 | G27: Male | H27: Average | I27: 47360
C28: Dennison Crosswaite | D28: 44271 | E28: Website | F28: 26 | H28: Above average | I28: 90700
C29: Dotty Strutley | D29: 44145 | E29: Website | F29: 31 | G29: Female | H29: Average | I29: 41980
C30: Drusy MacCombe | D30: 44820 | E30: Sales | F30: 28 | G30: Male | H30: Very poor | I30: 43510
C31: Dyna Doucette | D31: 44724 | E31: Procurement | F31: 31 | G31: Male | H31: Average | I31: 103550
C32: Ebonee Roxburgh | D32: 44701 | E32: Procurement | F32: 30 | G32: Male | H32: Average | I32: 67950
C33: Elia Cockton | D33: 44312 | E33: Website | F33: 33 | G33: Female | H33: Average | I33: 75280
C34: Enoch Dowrey | D34: 44236 | E34: Finance | F34: 27 | G34: Male | H34: Above average | I34: 91650
C35: Erin Androsik | D35: 44701 | E35: Procurement | F35: 33 | G35: Male | H35: Above average | I35: 48530
C36: Erin Androsik | D36: 44701 | E36: Procurement | F36: 33 | G36: Male | H36: Above average | I36: 48530
C37: Esmaria Denecamp | D37: 44567 | E37: Finance | F37: 27 | G37: Male | H37: Average | I37: 48980
C38: Ewart Laphorn | D38: 44122 | E38: HR | F38: 27 | G38: Female | H38: Average | I38: 119110
C39: Florinda Crace | D39: 44400 | E39: HR | F39: 32 | G39: Female | H39: Average | I39: 45510
C40: Gigi Bohling | D40: 44385 | E40: Sales | F40: 33 | G40: Male | H40: Average | I40: 74550
... C67: Madelene Upcott | D67: 44726 | E67: Procurement | F67: 25 | G67: Male | H67: Above average | I67: 109190
...

Sheet Raw Data 2
A1: Dataset: Synthetic HR employee data created for analytics and dashboarding purposes.
B3: Name | C3: Gender | D3: Age | E3: Rating | F3: Date Joined | G3: Department | H3: Salary
B4: Deepali Charan | C4: Male | D4: 20 | E4: Average | F4: 44122 | G4: Website | H4: 112650
B5: Yagna Sujeev | C5: Female | D5: 32 | E5: Above average | F5: 44293 | G5: Website | H5: 43840
B6: Satyendra Venkatadri | C6: Male | D6: 31 | E6: Average | F6: 44663 | G6: Procurement | H6: 103550
B7: Madhavdas Buhpathi | C7: Female | D7: 32 | E7: Average | F7: 44339 | G7: HR | H7: 45510
B8: Sahila Chandrasekhar | D8: 37 | E8: Poor | F8: 44085 | G8: Finance | H8: 115440
B9: Mirium Seemantini Shivakumar | C9: Female | D9: 38 | E9: Above average | F9: 44268 | G9: Sales | H9: 56870
B10: Purnendu Vijayarangan | C10: Female | D10: 25 | E10: Average | F10: 44144 | G10: Sales | H10: 92700
B11: Rukma Vinita | D11: 32 | E11: Average | F11: 44713 | G11: Website | H11: 91310
B12: Yauvani Tarpa | C12: Male | D12: 33 | E12: Average | F12: 44324 | G12: Sales | H12: 74550
B13: Damayanti Thangavadivelu | C13: Male | D13: 25 | E13: Above average | F13: 44665 | G13: Procurement | H13: 109190
B14: Manjusri Ruchi | C14: Female | D14: 40 | E14: Average | F14: 44320 | G14: Website | H14: 104410
B15: Mithil Nadkarni | C15: Male | D15: 30 | E15: Average | F15: 44544 | G15: Finance | H15: 96800
B16: Ardhendu Abhichandra Jayakar | C16: Male | D16: 28 | E16: Above average | F16: 43980 | G16: Finance | H16: 48170
B17: Akbar Sorabhjee | C17: Male | D17: 21 | E17: Average | F17: 44042 | G17: Procurement | H17: 37920
B18: Bandhula Sathyanna | C18: Male | D18: 34 | E18: Average | F18: 44642 | G18: Procurement | H18: 112650
B19: Daruka Ghazali | C19: Female | D19: 34 | E19: Poor | F19: 44660 | G19: Sales | H19: 49630
B20: Heer Pennathur | C20: Male | D20: 36 | E20: Average | F20: 43958 | G20: Website | H20: 118840
B21: Shekhar Eswara | C21: Male | D21: 30 | E21: Average | F21: 44789 | G21: Website | H21: 69710
B22: Udyan Lanka | C22: Male | D22: 20 | E22: Average | F22: 44683 | G22: Procurement | H22: 79570
B23: Shreela Ramasubraman | C23: Female | D23: 22 | E23: Above average | F23: 44388 | G23: Procurement | H23: 76900
... B54: Indu Varada Sumedh | C54: Female | D54: 28 | E54: Average | F54: 44124 | G54: Finance | H54: 75970
B55: Karuna Pashupathy | D55: 27 | E55: Above average | F55: 44212 | G55: Website | H55: 90700
B56: Mardav Ramaswami | C56: Male | D56: 30 | E56: Average | F56: 44607 | G56: Procurement | H56: 60570
B57: Sarayu Ragunathan | C57: Male | D57: 33 | E57: Average | F57: 44103 | G57: Procurement | H57: 115920
B58: Kevalkumar Solanki | C58: Female | D58: 33 | E58: Average | F58: 44006 | G58: Finance | H58: 65360
B59: Upendra Swati | D59: 30 | E59: Average | F59: 44535 | G59: Finance | H59: 64000
B60: Deepit Ranjana | C60: Female | D60: 34 | E60: Average | F60: 44383 | G60: Finance | H60: 92450
B61: Amal Nimesh | C61: Male | D61: 31 | E61: Average | F61: 44450 | G61: Website | H61: 48950
B62: Kunja Prashanta Vibha | C62: Female | D62: 27 | E62: Average | F62: 44625 | G62: Website | H62: 83750
B63: Godavari Veena | C63: Female | D63: 40 | E63: Average | F63: 44276 | G63: Website | H63: 87620
B64: Devasree Fullara Saurin | C64: Female | D64: 20 | E64: Poor | F64: 44476 | G64: Sales | H64: 68900
B65: Geena Raghavanpillai | C65: Male | D65: 32 | E65: Average | F65: 44403 | G65: Sales | H65: 53540
B66: Rupak Mehra | C66: Male | D66: 28 | E66: Very poor | F66: 44758 | G66: Sales | H66: 43510
B67: Sawini Chandan | C67: Female | D67: 38 | E67: Exceptional | F67: 44316 | G67: Sales | H67: 109160
B68: Baruna Ogale | C68: Male | D68: 40 | E68: Average | F68: 44204 | G68: Procurement | H68: 99750
B69: Jagajeet Viraj | C69: Female | D69: 31 | E69: Average | F69: 44084 | G69: Website | H69: 41980
B70: Kulbhushan Moorthy | C70: Male | D70: 36 | E70: Average | F70: 44272 | G70: Finance | H70: 71380
B71: Ilesh Dasgupta | C71: Male | D71: 27 | E71: Very poor | F71: 44547 | G71: Procurement | H71: 113280
...
